<?xml version="1.0" ?>
<!-- =================================================================================== -->
<!-- |    This document was autogenerated by xacro from toto.xacro                     | -->
<!-- |    EDITING THIS FILE BY HAND IS NOT RECOMMENDED                                 | -->
<!-- =================================================================================== -->


<robot name="toto">
  
  <!-- BASE LINKS AND JOINTS OF ROBOT ARE IN THIS THESE ALLOW THE ROBOT TO NAVIGATE-->
  <link name="base_link">
    <inertial>
      <origin rpy="0 0 0" xyz="-6.090306880278278e-16 0.002513049838439521 0.1635865428520959"/>
      <mass value="7.0"/>
      <inertia ixx="0.380455" ixy="0.0" ixz="-0.0" iyy="0.569614" iyz="0.004146" izz="0.629258"/>
    </inertial>
    <visual>
      <origin rpy="0 0 -1.57079633" xyz="0 0 0"/>
      <geometry>
        <mesh filename="package://toto2_gazebo/models/toto/meshes/base_link.stl" scale="0.001 0.001 0.001"/>
      </geometry>
      <material name="silver"/>
    </visual>
    <collision>
      <origin rpy="0 0 -1.57079633" xyz="0 0 0"/>
      <geometry>
        <mesh filename="package://toto2_gazebo/models/toto/meshes/base_link.stl" scale="0.001 0.001 0.001"/>
      </geometry>
    </collision>
  </link>
  <link name="right_wheel_1">
    <inertial>
      <origin rpy="0 0 0" xyz="0.03541204935975309 -2.4243289958354717e-14 -9.020562075079397e-17"/>
      <mass value="0.3"/>
      <inertia ixx="0.002407" ixy="-0.0" ixz="0.0" iyy="0.001396" iyz="0.0" izz="0.001396"/>
    </inertial>
    <visual>
      <origin rpy="0 0 0" xyz="-0.1195 0.0 -0.05"/>
      <geometry>
        <mesh filename="package://toto2_gazebo/models/toto/meshes/right_wheel_1.stl" scale="0.001 0.001 0.001"/>
      </geometry>
      <material name="silver"/>
    </visual>
    <collision>
      <origin rpy="0 0 0" xyz="-0.1195 0.0 -0.05"/>
      <geometry>
        <mesh filename="package://toto2_gazebo/models/toto/meshes/right_wheel_1.stl" scale="0.001 0.001 0.001"/>
      </geometry>
    </collision>
  </link>
  <link name="left_wheel_1">
    <inertial>
      <origin rpy="0 0 0" xyz="-0.03541204935975312 4.3327407697699233e-14 -6.245004513516506e-17"/>
      <mass value="0.3"/>
      <inertia ixx="0.002407" ixy="0.0" ixz="0.0" iyy="0.001396" iyz="0.0" izz="0.001396"/>
    </inertial>
    <visual>
      <origin rpy="0 0 0" xyz="0.1195 0.0 -0.05"/>
      <geometry>
        <mesh filename="package://toto2_gazebo/models/toto/meshes/left_wheel_1.stl" scale="0.001 0.001 0.001"/>
      </geometry>
      <material name="silver"/>
    </visual>
    <collision>
      <origin rpy="0 0 0" xyz="0.1195 0.0 -0.05"/>
      <geometry>
        <mesh filename="package://toto2_gazebo/models/toto/meshes/left_wheel_1.stl" scale="0.001 0.001 0.001"/>
      </geometry>
    </collision>
  </link>
  <joint name="left_wheel_joint" type="continuous">
    <origin rpy="0 0 -1.57079633" xyz=" 0.0 0.1195 0.0499"/>
    <parent link="base_link"/>
    <child link="left_wheel_1"/>
    <axis xyz="-1.0 0.0 0.0"/>
  </joint>
  <joint name="right_wheel_joint" type="continuous">
    <origin rpy="0 0 -1.57079633" xyz="0.0 -0.1195 0.0499"/>
    <parent link="base_link"/>
    <child link="right_wheel_1"/>
    <axis xyz="-1.0 0.0 0.0"/>
  </joint>

  <gazebo reference="base_link">
    <material>Gazebo/Silver</material>
    <mu1>0</mu1>
    <mu2>0</mu2>
    <selfCollide>true</selfCollide>
    <gravity>true</gravity>
  </gazebo>
  <gazebo reference="right_wheel_1">
    <material>Gazebo/Silver</material>
    <mu1>10</mu1>
    <mu2>10</mu2>
    <selfCollide>true</selfCollide>
  </gazebo>
  <gazebo reference="left_wheel_1">
    <material>Gazebo/Silver</material>
    <mu1>10</mu1>
    <mu2>10</mu2>
    <selfCollide>true</selfCollide>
  </gazebo>
  <gazebo reference="lidar_1">
    <material>Gazebo/Silver</material>
    <mu1>0.2</mu1>
    <mu2>0.2</mu2>
    <selfCollide>true</selfCollide>
  </gazebo>
  <gazebo reference="camera_base_1">
    <material>Gazebo/Silver</material>
    <mu1>0.2</mu1>
    <mu2>0.2</mu2>
    <selfCollide>true</selfCollide>
  </gazebo>
  <gazebo reference="camera_link1_1">
    <material>Gazebo/Silver</material>
    <mu1>0.2</mu1>
    <mu2>0.2</mu2>
    <selfCollide>true</selfCollide>
  </gazebo>
  <gazebo reference="camera_link2_1">
    <material>Gazebo/Silver</material>
    <mu1>0.2</mu1>
    <mu2>0.2</mu2>
    <selfCollide>true</selfCollide>
  </gazebo>
  <gazebo reference="camera_1">
    <material>Gazebo/Silver</material>
    <mu1>0.2</mu1>
    <mu2>0.2</mu2>
    <selfCollide>true</selfCollide>
  </gazebo>

  <!-- THE FOLLOWING ARE SENSOR DESCRIPTORS-->
  <!-- LIDAR -->
  <link name="lidar_1">
    <inertial>
      <origin rpy="0 0 0" xyz="2.2068762530809514e-10 0.08500000036781817 -0.07958250099962488"/>
      <mass value="0.2"/>
      <inertia ixx="0.000336" ixy="0.0" ixz="-0.0" iyy="0.000279" iyz="-0.0" izz="0.000513"/>
    </inertial>
    <visual>
      <origin rpy="0 0 0" xyz="0.0 -0.085 -0.17"/>
      <geometry>
        <mesh filename="package://toto2_gazebo/models/toto/meshes/lidar_1.stl" scale="0.001 0.001 0.001"/>
      </geometry>
      <material name="silver"/>
    </visual>
    <collision>
      <origin rpy="0 0 0" xyz="0.0 -0.085 -0.17"/>
      <geometry>
        <mesh filename="package://toto2_gazebo/models/toto/meshes/lidar_1.stl" scale="0.001 0.001 0.001"/>
      </geometry>
    </collision>
  </link>
  <joint name="lidar_joint" type="fixed">
    <parent link="base_link"/>
    <child link="lidar_1"/>
    <origin rpy="0 0 3.1415" xyz="0.1 0.0 0.17"/>
  </joint>
  <!-- CAMERA -->
  <link name="camera_link1_1">
  </link>
  <link name="camera_link2_1">
  </link>
  <link name="camera_1">
  </link>
  <joint name="camera_joint_1" type="fixed">
    <parent link="base_link"/>
    <child link="camera_link1_1"/>
    <origin rpy="0 0 0" xyz="0.16 0.0 0.2795"/>
    <axis xyz="0.0 0.0 1.0"/>
  </joint>
  <joint name="camera_joint_2" type="fixed">
    <parent link="camera_link1_1"/>
    <child link="camera_link2_1"/>
    <origin rpy="0 0 0" xyz="0.03 0.0 0.042"/>
    <axis xyz="0.0 1.0 0.0"/>
  </joint>
  <joint name="camera_joint" type="fixed">
    <parent link="camera_link2_1"/>
    <child link="camera_1"/>
    <origin rpy="0 0 0" xyz="0.020 0.01 0.015"/>
  </joint>


  <material name="silver">
    <color rgba="0.700 0.700 0.700 1.000"/>
  </material>
  <transmission name="right_wheel_joint_tran">
    <type>transmission_interface/SimpleTransmission</type>
    <joint name="right_wheel_joint">
      <hardwareInterface>hardware_interface/EffortJointInterface</hardwareInterface>
    </joint>
    <actuator name="right_wheel_joint_actr">
      <hardwareInterface>hardware_interface/EffortJointInterface</hardwareInterface>
      <mechanicalReduction>1</mechanicalReduction>
    </actuator>
  </transmission>
  <transmission name="left_wheel_joint_tran">
    <type>transmission_interface/SimpleTransmission</type>
    <joint name="left_wheel_joint">
      <hardwareInterface>hardware_interface/EffortJointInterface</hardwareInterface>
    </joint>
    <actuator name="left_wheel_joint_actr">
      <hardwareInterface>hardware_interface/EffortJointInterface</hardwareInterface>
      <mechanicalReduction>1</mechanicalReduction>
    </actuator>
  </transmission>
  <!-- <transmission name="camera_joint_1_tran">
    <type>transmission_interface/SimpleTransmission</type>
    <joint name="camera_joint_1">
      <hardwareInterface>hardware_interface/PositionJointInterface</hardwareInterface>
    </joint>
    <actuator name="camera_joint_1_actr">
      <hardwareInterface>hardware_interface/PositionJointInterface</hardwareInterface>
      <mechanicalReduction>1</mechanicalReduction>
    </actuator>
  </transmission>

  <transmission name="camera_joint_2_tran">
    <type>transmission_interface/SimpleTransmission</type>
    <joint name="camera_joint_2">
      <hardwareInterface>hardware_interface/PositionJointInterface</hardwareInterface>
    </joint>
    <actuator name="camera_joint_2_actr">
      <hardwareInterface>hardware_interface/PositionJointInterface</hardwareInterface>
      <mechanicalReduction>1</mechanicalReduction>
    </actuator>
  </transmission> -->
  <gazebo>
    <plugin filename="libgazebo_ros_control.so" name="control">
      <robotNamespace>/toto</robotNamespace>
    </plugin>
  </gazebo>
  <!-- Differential Drive -->
  <gazebo>
    <plugin filename="libgazebo_ros_diff_drive.so" name="differential_drive_controller">
      <!-- Plugin update rate in Hz -->
      <updateRate>30</updateRate>
      <!-- Name of left joint, defaults to `left_joint` -->
      <leftJoint>left_wheel_joint</leftJoint>
      <!-- Name of right joint, defaults to `right_joint` -->
      <rightJoint>right_wheel_joint</rightJoint>
      <!-- The distance from the center of one wheel to the other, in meters, defaults to 0.34 m -->
      <wheelSeparation>0.3150</wheelSeparation>
      <!-- Diameter of the wheels, in meters, defaults to 0.15 m -->
      <wheelDiameter>0.10</wheelDiameter>
      <!-- Wheel acceleration, in rad/s^2, defaults to 0.0 rad/s^2 -->
      <wheelAcceleration>1.0</wheelAcceleration>
      <!-- Maximum torque which the wheels can produce, in Nm, defaults to 5 Nm -->
      <wheelTorque>20</wheelTorque>
      <!-- Topic to receive geometry_msgs/Twist message commands, defaults to `cmd_vel` -->
      <commandTopic>/cmd_vel</commandTopic>
      <!-- Topic to publish nav_msgs/Odometry messages, defaults to `odom` -->
      <odometryTopic>odom</odometryTopic>
      <!-- Odometry frame, defaults to `odom` -->
      <odometryFrame>odom</odometryFrame>
      <!-- Robot frame to calculate odometry from, defaults to `base_footprint` -->
      <robotBaseFrame>base_link</robotBaseFrame>
      <!-- Odometry source, 0 for ENCODER, 1 for WORLD, defaults to WORLD -->
      <odometrySource>1</odometrySource>
      <!-- Set to true to publish transforms for the wheel links, defaults to false -->
      <publishWheelTF>true</publishWheelTF>
      <!-- Set to true to publish transforms for the odometry, defaults to true -->
      <publishOdom>true</publishOdom>
      <!-- Set to true to publish sensor_msgs/JointState on /joint_states for the wheel joints, defaults to false -->
      <publishWheelJointState>true</publishWheelJointState>
      <!-- Set to true to swap right and left wheels, defaults to true -->
      <legacyMode>false</legacyMode>
    </plugin>
  </gazebo>
  <!-- lidar -->
  <gazebo reference="lidar_1">
    <sensor name="head_hokuyo_sensor" type="ray">
      <pose>0 0 0 0 0 0</pose>
      <visualize>false</visualize>
      <update_rate>30</update_rate>
      <ray>
        <scan>
          <horizontal>
            <samples>720</samples>
            <resolution>1</resolution>
            <min_angle>-3.14159</min_angle>
            <max_angle>3.14159</max_angle>
          </horizontal>
        </scan>
        <range>
          <min>0.06</min>
          <max>20.0</max>
          <resolution>0.01</resolution>
        </range>
        <noise>
          <type>gaussian</type>
          <!-- Noise parameters based on published spec for Hokuyo laser
              achieving "+-30mm" accuracy at range < 10m.  A mean of 0.0m and
              stddev of 0.01m will put 99.7% of samples within 0.03m of the true
              reading. -->
          <mean>0.0</mean>
          <stddev>0.01</stddev>
        </noise>
      </ray>
      <plugin filename="libgazebo_ros_laser.so" name="gazebo_ros_head_hokuyo_controller">
        <topicName>/scan</topicName>
        <frameName>lidar_1</frameName>
      </plugin>
    </sensor>
  </gazebo>
  <!-- camera -->
  <gazebo reference="camera_1">
    <sensor name="camera1" type="camera">
      <update_rate>30.0</update_rate>
      <camera name="head">
        <horizontal_fov>1.3962634</horizontal_fov>
        <image>
          <width>800</width>
          <height>800</height>
          <format>R8G8B8</format>
        </image>
        <clip>
          <near>0.02</near>
          <far>300</far>
        </clip>
        <noise>
          <type>gaussian</type>
          <!-- Noise is sampled independently per pixel on each frame.
              That pixel's noise value is added to each of its color
              channels, which at that point lie in the range [0,1]. -->
          <mean>0.0</mean>
          <stddev>0.007</stddev>
        </noise>
      </camera>
      <plugin filename="libgazebo_ros_camera.so" name="camera_controller">
        <alwaysOn>true</alwaysOn>
        <updateRate>0.0</updateRate>
        <cameraName>TOTO/camera1</cameraName>
        <imageTopicName>/image_raw</imageTopicName>
        <cameraInfoTopicName>/camera_info</cameraInfoTopicName>
        <frameName>camera_1</frameName>
        <hackBaseline>0.07</hackBaseline>
        <distortionK1>0.0</distortionK1>
        <distortionK2>0.0</distortionK2>
        <distortionK3>0.0</distortionK3>
        <distortionT1>0.0</distortionT1>
        <distortionT2>0.0</distortionT2>
      </plugin>
    </sensor>
  </gazebo>
</robot>