<?xml version="1.0" ?>
<sdf version="1.5">
  <model name="fusion_arm">
    <static>false</static>

    <!-- **************************** BASE_FOOTPRINT ********************************* -->

    <link name="base_footprint"/>

    <!-- **************************** BASE_LINK ********************************* -->

    <link name="base_link">
      <inertial>
        <pose>0.0003347701550377962 0.0002467868808562595 0.016426104833341764 0 0 0</pose>
        <inertia>
          <ixx>4.1e-05</ixx>
          <iyy>4.2e-05</iyy>
          <izz>3.3e-05</izz>
          <ixy>0.0</ixy>
          <iyz>0.0</iyz>
          <ixz>0.0</ixz>
        </inertia>
        <mass>0.22306073060929593</mass>
      </inertial>

      <visual name="base_visual">
        <pose> 0 0 0 0 0 0</pose>
        <geometry>
          <mesh>
            <uri>model://fusion_arm/meshes/base_link.stl</uri>
            <scale>0.001 0.001 0.001 </scale>
          </mesh>
        </geometry>
      </visual>

      <collision name="base_collision">
        <pose>0 0 0 0 0 0</pose>
        <geometry>
          <mesh>
            <uri>model://fusion_arm/meshes/base_link.stl</uri>
            <scale>0.001 0.001 0.001 </scale>
          </mesh>
        </geometry>
      </collision>
    </link>

    <!-- **************************** LINKS ********************************* -->

    <link name="link_1_1">
      <inertial>
        <pose>0.014335399579242975 0.0019995312441046563 0.01003709414126474 0 0 0</pose>
        <inertia>
          <ixx>1.8438E-06</ixx>
          <iyy>2.493E-06</iyy>
          <izz>1.1823E-06</izz>
          <ixy>0.0</ixy>
          <iyz>0.0</iyz>
          <ixz>0.0</ixz>
        </inertia>
        <mass>0.013456150233067987</mass>
      </inertial>

      <visual name="link_1_1_visual">
        <pose>0 0 0 0 0 0</pose>
        <geometry>
          <mesh>
            <uri>model://fusion_arm/meshes/link_1_1.stl</uri>
            <scale>0.001 0.001 0.001 </scale>
          </mesh>
        </geometry>
      </visual>

      <collision name="link_1_1_collision">
        <pose>0 0 0 0 0 0</pose>
        <geometry>
          <mesh>
            <uri>model://fusion_arm/meshes/link_1_1.stl</uri>
            <scale>0.001 0.001 0.001 </scale>
          </mesh>
        </geometry>
      </collision>
    </link>

    <link name="link_2_1">
      <inertial>
        <pose>0.01749956035430031 -0.0020004687558953117 -3.1822259197178404e-07 0 0 0</pose>
        <inertia>
          <ixx>0.0</ixx>
          <iyy>2.493E-06</iyy>
          <izz>1.1823E-06</izz>
          <ixy>0.0</ixy>
          <iyz>0.0</iyz>
          <ixz>0.0</ixz>
        </inertia>
        <mass>0.013456150233067987</mass>
      </inertial>

      <visual name="link_2_1_visual">
        <pose>0 0 0 0 0 0</pose>
        <geometry>
          <mesh>
            <uri>model://fusion_arm/meshes/link_2_1.stl</uri>
            <scale>0.001 0.001 0.001 </scale>
          </mesh>
        </geometry>
      </visual>

      <collision name="link_2_1_collision">
        <pose>0 0 0 0 0 0</pose>
        <geometry>
          <mesh>
            <uri>model://fusion_arm/meshes/link_2_1.stl</uri>
            <scale>0.001 0.001 0.001 </scale>
          </mesh>
        </geometry>
      </collision>
    </link>


    <!-- **************************** JOINTS ********************************* -->

    <joint name="rigid_1" type="continuous">
      <pose>0.015762 0.006955 0.054099 0 0 0</pose>
      <parent>base_link</parent>
      <child>link_1_1</child>
      <axis>
        <xyz>0.0 1.0 0.0</xyz>
      </axis>
    </joint>

    <joint name="rigid_2" type="continuous">
      <pose>0.028671 0.0 0.020075 0 0 0</pose>
      <parent>link_1_1</parent>
      <child>link_2_1</child>
      <axis>
        <xyz>0.0 1.0 0.0</xyz>
      </axis>
    </joint>


    <joint name="base_joint" type="fixed">
      <parent>base_footprint</parent>
      <child>base_link</child>
      <pose>0.0 0.0 0.1 0 0 0</pose>
      <axis>
        <xyz>0 0 1.0</xyz>
      </axis>
    </joint>


    <!-- *********************** JOINT STATE PUBLISHER *********************   -->

    <plugin name="fusion_arm_joint_state" filename="libgazebo_ros_joint_state_publisher.so">
      <ros>
        <remapping>~/out:=joint_states</remapping>
      </ros>
      <update_rate>30</update_rate>
      <joint_name>rigid_1</joint_name>
      <joint_name>rigid_2</joint_name>
    </plugin>

  </model>
</sdf>
