<?xml version="1.0" ?>
<robot name="toto" xmlns:xacro="http://www.ros.org/wiki/xacro">

<xacro:include filename="$(find TOTO_desc)/urdf/materials.xacro" />
<xacro:include filename="$(find TOTO_desc)/urdf/TOTO.trans" />
<xacro:include filename="$(find TOTO_desc)/urdf/TOTO.gazebo" />
<link name="base_link">
  <inertial>
    <origin xyz="-6.090306880278278e-16 0.002513049838439521 0.1635865428520959" rpy="0 0 0"/>
    <mass value="22.50861822493245"/>
    <inertia ixx="0.380455" iyy="0.569614" izz="0.629258" ixy="0.0" iyz="0.004146" ixz="-0.0"/>
  </inertial>
  <visual>
    <origin xyz="0 0 0" rpy="0 0 0"/>
    <geometry>
      <mesh filename="package://TOTO_desc/meshes/base_link.stl" scale="0.001 0.001 0.001"/>
    </geometry>
    <material name="silver"/>
  </visual>
  <collision>
    <origin xyz="0 0 0" rpy="0 0 0"/>
    <geometry>
      <mesh filename="package://TOTO_desc/meshes/base_link.stl" scale="0.001 0.001 0.001"/>
    </geometry>
  </collision>
</link>

<link name="right_wheel_1">
  <inertial>
    <origin xyz="0.03541204935975309 -2.4243289958354717e-14 -9.020562075079397e-17" rpy="0 0 0"/>
    <mass value="1.9848307984113491"/>
    <inertia ixx="0.002407" iyy="0.001396" izz="0.001396" ixy="-0.0" iyz="0.0" ixz="0.0"/>
  </inertial>
  <visual>
    <origin xyz="-0.1195 0.0 -0.05" rpy="0 0 0"/>
    <geometry>
      <mesh filename="package://TOTO_desc/meshes/right_wheel_1.stl" scale="0.001 0.001 0.001"/>
    </geometry>
    <material name="silver"/>
  </visual>
  <collision>
    <origin xyz="-0.1195 0.0 -0.05" rpy="0 0 0"/>
    <geometry>
      <mesh filename="package://TOTO_desc/meshes/right_wheel_1.stl" scale="0.001 0.001 0.001"/>
    </geometry>
  </collision>
</link>

<link name="left_wheel_1">
  <inertial>
    <origin xyz="-0.03541204935975312 4.3327407697699233e-14 -6.245004513516506e-17" rpy="0 0 0"/>
    <mass value="1.9848307984113438"/>
    <inertia ixx="0.002407" iyy="0.001396" izz="0.001396" ixy="0.0" iyz="0.0" ixz="0.0"/>
  </inertial>
  <visual>
    <origin xyz="0.1195 0.0 -0.05" rpy="0 0 0"/>
    <geometry>
      <mesh filename="package://TOTO_desc/meshes/left_wheel_1.stl" scale="0.001 0.001 0.001"/>
    </geometry>
    <material name="silver"/>
  </visual>
  <collision>
    <origin xyz="0.1195 0.0 -0.05" rpy="0 0 0"/>
    <geometry>
      <mesh filename="package://TOTO_desc/meshes/left_wheel_1.stl" scale="0.001 0.001 0.001"/>
    </geometry>
  </collision>
</link>

<link name="lidar_1">
  <inertial>
    <origin xyz="2.2068762530809514e-10 0.08500000036781817 -0.07958250099962488" rpy="0 0 0"/>
    <mass value="0.7313345049459391"/>
    <inertia ixx="0.000336" iyy="0.000279" izz="0.000513" ixy="0.0" iyz="-0.0" ixz="-0.0"/>
  </inertial>
  <visual>
    <origin xyz="0.0 0.0 -0.281" rpy="0 0 0"/>
    <geometry>
      <mesh filename="package://TOTO_desc/meshes/lidar_1.stl" scale="0.001 0.001 0.001"/>
    </geometry>
    <material name="silver"/>
  </visual>
  <collision>
    <origin xyz="0.0 0.0 -0.281" rpy="0 0 0"/>
    <geometry>
      <mesh filename="package://TOTO_desc/meshes/lidar_1.stl" scale="0.001 0.001 0.001"/>
    </geometry>
  </collision>
</link>

<!-- <link name="lidar_1">
  <inertial>
    <origin xyz="2.2068762530809514e-10 0.08500000036781817 -0.07958250099962488" rpy="0 0 0"/>
    <mass value="0.7313345049459391"/>
    <inertia ixx="0.000336" iyy="0.000279" izz="0.000513" ixy="0.0" iyz="-0.0" ixz="-0.0"/>
  </inertial>
  <visual>
    <origin xyz="0.0 0.0 -0.095" rpy="0 0 0"/>
    <geometry>
      <cylinder length="0.02" radius="0.04"/>
    </geometry>
    <material name="silver"/>
  </visual>
  <collision>
    <origin xyz="0.0 0.0 -0.095" rpy="0 0 0"/>
    <geometry>
      <cylinder length="0.02" radius="0.04"/>
    </geometry>
  </collision>
</link> -->

<link name="camera_base_1">
  <inertial>
    <origin xyz="5.329070518200751e-17 0.15449999999999992 -0.10350000000000009" rpy="0 0 0"/>
    <mass value="0.027936552111872705"/>
    <inertia ixx="2e-06" iyy="4e-06" izz="6e-06" ixy="-0.0" iyz="-0.0" ixz="-0.0"/>
  </inertial>
  <visual>
    <origin xyz="-0.0 0.0 -0.3826" rpy="0 0 0"/>
    <geometry>
      <mesh filename="package://TOTO_desc/meshes/camera_base_1.stl" scale="0.001 0.001 0.001"/>
    </geometry>
    <material name="silver"/>
  </visual>
  <collision>
    <origin xyz="-0.0 0.0 -0.3826" rpy="0 0 0"/>
    <geometry>
      <mesh filename="package://TOTO_desc/meshes/camera_base_1.stl" scale="0.001 0.001 0.001"/>
    </geometry>
  </collision>
</link>

<link name="camera_link1_1">
  <inertial>
    <origin xyz="3.5517605492410855e-17 -8.326672684688674e-17 0.021977671314545866" rpy="0 0 0"/>
    <mass value="0.017241343895667487"/>
    <inertia ixx="3e-06" iyy="3e-06" izz="0.0" ixy="0.0" iyz="0.0" ixz="-0.0"/>
  </inertial>
  <visual>
    <origin xyz="-0.0 -0.1545 -0.2806" rpy="0 0 0"/>
    <geometry>
      <mesh filename="package://TOTO_desc/meshes/camera_link1_1.stl" scale="0.001 0.001 0.001"/>
    </geometry>
    <material name="silver"/>
  </visual>
  <collision>
    <origin xyz="-0.0 -0.1545 -0.2806" rpy="0 0 0"/>
    <geometry>
      <mesh filename="package://TOTO_desc/meshes/camera_link1_1.stl" scale="0.001 0.001 0.001"/>
    </geometry>
  </collision>
</link>

<link name="camera_link2_1">
  <inertial>
    <origin xyz="0.0025000000000000347 0.017740216570916262 0.0031234630643570127" rpy="0 0 0"/>
    <mass value="0.017258646715228157"/>
    <inertia ixx="3e-06" iyy="0.0" izz="3e-06" ixy="-0.0" iyz="-0.0" ixz="0.0"/>
  </inertial>
  <visual>
    <origin xyz="-0.0025 -0.1545 -0.3206" rpy="0 0 0"/>
    <geometry>
      <mesh filename="package://TOTO_desc/meshes/camera_link2_1.stl" scale="0.001 0.001 0.001"/>
    </geometry>
    <material name="silver"/>
  </visual>
  <collision>
    <origin xyz="-0.0025 -0.1545 -0.3206" rpy="0 0 0"/>
    <geometry>
      <mesh filename="package://TOTO_desc/meshes/camera_link2_1.stl" scale="0.001 0.001 0.001"/>
    </geometry>
  </collision>
</link>

<link name="camera_1">
  <inertial>
    <origin xyz="3.5561831257524545e-17 0.0014775246115884266 0.0002603998777516159" rpy="0 0 0"/>
    <mass value="0.021195000000000047"/>
    <inertia ixx="2e-06" iyy="3e-06" izz="2e-06" ixy="0.0" iyz="0.0" ixz="-0.0"/>
  </inertial>
  <visual>
    <origin xyz="-0.005 -0.193892 -0.327546" rpy="0 0 0"/>
    <geometry>
      <mesh filename="package://TOTO_desc/meshes/camera_1.stl" scale="0.001 0.001 0.001"/>
    </geometry>
    <material name="silver"/>
  </visual>
  <collision>
    <origin xyz="-0.005 -0.193892 -0.327546" rpy="0 0 0"/>
    <geometry>
      <mesh filename="package://TOTO_desc/meshes/camera_1.stl" scale="0.001 0.001 0.001"/>
    </geometry>
  </collision>
</link>

<joint name="right_wheel_joint" type="continuous">
  <origin xyz="0.1195 0.0 0.0499" rpy="0 0 0"/>
  <parent link="base_link"/>
  <child link="right_wheel_1"/>
  <axis xyz="-1.0 -0.0 0.0"/>
</joint>

<joint name="left_wheel_joint" type="continuous">
  <origin xyz="-0.1195 0.0 0.0499" rpy="0 0 0"/>
  <parent link="base_link"/>
  <child link="left_wheel_1"/>
  <axis xyz="-1.0 -0.0 0.0"/>
</joint>

<joint name="lidar_joint" type="fixed">
  <origin xyz="0.0 0.0 0.281" rpy="0 0 0"/>
  <parent link="base_link"/>
  <child link="lidar_1"/>
</joint>

<joint name="camera_base_joint" type="fixed">
  <origin xyz="0.0 0.0 0.3826" rpy="0 0 0"/>
  <parent link="base_link"/>
  <child link="camera_base_1"/>
</joint>

<!-- <joint name="camera_joint_1" type="continuous">
  <origin xyz="0.0 0.1545 -0.102" rpy="0 0 0"/>
  <parent link="camera_base_1"/>
  <child link="camera_link1_1"/>
  <axis xyz="-0.0 0.0 1.0"/>
</joint> -->

<joint name="camera_joint_1" type="fixed">
  <origin xyz="0.0 0.1545 -0.102" rpy="0 0 0"/>
  <parent link="camera_base_1"/>
  <child link="camera_link1_1"/>
</joint>

<!-- <joint name="camera_joint_2" type="revolute">
  <origin xyz="0.0025 0.0 0.04" rpy="0 0 0"/>
  <parent link="camera_link1_1"/>
  <child link="camera_link2_1"/>
  <axis xyz="1.0 0.0 0.0"/>
  <limit upper="2.007129" lower="0.174533" effort="100" velocity="100"/>
</joint> -->

<!-- <joint name="camera_joint_2" type="continuous">
  <origin xyz="0.0025 0.0 0.04" rpy="0 0 0"/>
  <parent link="camera_link1_1"/>
  <child link="camera_link2_1"/>
  <axis xyz="1.0 0.0 0.0"/>
</joint> -->

<joint name="camera_joint_2" type="fixed">
  <origin xyz="0.0025 0.0 0.04" rpy="-0.17 0 0"/>
  <parent link="camera_link1_1"/>
  <child link="camera_link2_1"/>
</joint>

<joint name="camera_joint_3" type="fixed">
  <origin xyz="0.0025 0.039392 0.006946" rpy="0 0 0"/>
  <parent link="camera_link2_1"/>
  <child link="camera_1"/>
</joint>

</robot>
